Workbook

Sheet Labels
A1: =Overview_Report!B6 & Overview_Report!$C$2 -> DC In to Stock -Actual | B1: =Overview_Report!B6 & " - wk"&RIGHT(Overview_Report!$I$5,2)&" FC" -> DC In to Stock - wk37 FC
A2: =Overview_Report!B7 & Overview_Report!$C$2 -> Total DC In to Stock (Queue Corrected) -Actual | B2: =Overview_Report!B7 & " - wk"&RIGHT(Overview_Report!$I$5,2)&" FC" -> Total DC In to Stock (Queue Corrected) - wk37 FC
A3: =Overview_Report!B8 & Overview_Report!$C$2 -> DC In to Stock from other BU -Actual | B3: =Overview_Report!B8 & " - wk"&RIGHT(Overview_Report!$I$5,2)&" FC" -> DC In to Stock from other BU - wk37 FC
A4: =Overview_Report!B9 & Overview_Report!$C$2 -> DC Replenishment and Other Inflow -Actual | B4: =Overview_Report!B9 & " - wk"&RIGHT(Overview_Report!$I$5,2)&" FC" -> DC Replenishment and Other Inflow - wk37 FC
A5: =Overview_Report!B10 & Overview_Report!$C$2 -> Total Transit IN -Actual | B5: =Overview_Report!B10 & " - wk"&RIGHT(Overview_Report!$I$5,2)&" FC" -> Total Transit IN - wk37 FC
A6: =Overview_Report!B11 & Overview_Report!$C$2 -> Total Inflow -Actual | B6: =Overview_Report!B11 & " - wk"&RIGHT(Overview_Report!$I$5,2)&" FC" -> Total Inflow - wk37 FC
A7: =Overview_Report!B12 & Overview_Report!$C$2 -> Total Inflow (Queue Corrected) -Actual | B7: =Overview_Report!B12 & " - wk"&RIGHT(Overview_Report!$I$5,2)&" FC" -> Total Inflow (Queue Corrected) - wk37 FC
A8: =Overview_Report!B13 & Overview_Report!$C$2 -> Land Volume (DC Stock) -Actual | B8: =Overview_Report!B13 & " - wk"&RIGHT(Overview_Report!$I$5,2)&" FC" -> Land Volume (DC Stock) - wk37 FC
A9: =Overview_Report!B14 & Overview_Report!$C$2 -> Land Volume (Transit) -Actual | B9: =Overview_Report!B14 & " - wk"&RIGHT(Overview_Report!$I$5,2)&" FC" -> Land Volume (Transit) - wk37 FC
A10: =Overview_Report!B15 & Overview_Report!$C$2 -> Ocean Volume (DC Stock) -Actual | B10: =Overview_Report!B15 & " - wk"&RIGHT(Overview_Report!$I$5,2)&" FC" -> Ocean Volume (DC Stock) - wk37 FC
A11: =Overview_Report!B16 & Overview_Report!$C$2 -> Ocean Volume (Transit) -Actual | B11: =Overview_Report!B16 & " - wk"&RIGHT(Overview_Report!$I$5,2)&" FC" -> Ocean Volume (Transit) - wk37 FC
A12: =Overview_Report!B17 & Overview_Report!$C$2 -> - -Actual | B12: =Overview_Report!B17 & " - wk"&RIGHT(Overview_Report!$I$5,2)&" FC" -> - - wk37 FC
... A38: =Overview_Report!B43 & Overview_Report!$C$2 -> Container m3 in Queue -Actual | B38: =Overview_Report!B43 & " - wk"&RIGHT(Overview_Report!$I$5,2)&" FC" -> Container m3 in Queue - wk37 FC
A39: =Overview_Report!B45 & Overview_Report!$C$2 -> Stock incl. Queue -Actual | B39: =Overview_Report!B45 & " - wk"&RIGHT(Overview_Report!$I$5,2)&" FC" -> Stock incl. Queue - wk37 FC
A40: =Overview_Report!B46 & Overview_Report!$C$2 -> Main Building Stock -Actual | B40: =Overview_Report!B46 & " - wk"&RIGHT(Overview_Report!$I$5,2)&" FC" -> Main Building Stock - wk37 FC
A41: =Overview_Report!B47 & Overview_Report!$C$2 -> Main Building Capacity m3 -Actual | B41: =Overview_Report!B47 & " - wk"&RIGHT(Overview_Report!$I$5,2)&" FC" -> Main Building Capacity m3 - wk37 FC
A42: =Overview_Report!B48 & Overview_Report!$C$2 -> Main Building Storage Utilization -Actual | B42: =Overview_Report!B48 & " - wk"&RIGHT(Overview_Report!$I$5,2)&" FC" -> Main Building Storage Utilization - wk37 FC
A43: =Overview_Report!B49 & Overview_Report!$C$2 -> External Stock -Actual | B43: =Overview_Report!B49 & " - wk"&RIGHT(Overview_Report!$I$5,2)&" FC" -> External Stock - wk37 FC
A44: =Overview_Report!B50 & Overview_Report!$C$2 -> External Capacity m3 -Actual | B44: =Overview_Report!B50 & " - wk"&RIGHT(Overview_Report!$I$5,2)&" FC" -> External Capacity m3 - wk37 FC

Sheet Overview_Report
N1: Hand. Cap. Ut. | P1: =AVERAGE(Sheet1!A3:A28) -> 0.6879673
C2: -Actual | N2: Stock S&E | O2: =_xlfn.XLOOKUP("Total Storage Utilization",$B:$B,I:I) -> 0.55780816 | P2: =_xlfn.XLOOKUP("Total Storage Utilization",$B:$B,AH:AH) -> 0.4889366
C3: Actuals | I3: Forecast
B5: DC_Overview_Measures | C5: ='Paste Here'!B1 -> 202631 | D5: ='Paste Here'!C1 -> 202632 | E5: ='Paste Here'!D1 -> 202633 | F5: ='Paste Here'!E1 -> 202634 | G5: ='Paste Here'!F1 -> 202635 | H5: ='Paste Here'!G1 -> 202636 | I5: ='Paste Here'!H1 -> 202637 | J5: ='Paste Here'!I1 -> 202638 | ... AH5: ='Paste Here'!AG1 -> 202709
B6: DC In to Stock | C6: =IFERROR(_xlfn.XLOOKUP($B6,'Paste Here'!$A:$A,'Paste Here'!B:B),0) -> 12448.036 | D6: =IFERROR(_xlfn.XLOOKUP($B6,'Paste Here'!$A:$A,'Paste Here'!C:C),0) -> 11717.21 | E6: =IFERROR(_xlfn.XLOOKUP($B6,'Paste Here'!$A:$A,'Paste Here'!D:D),0) -> 10275.364 | F6: =IFERROR(_xlfn.XLOOKUP($B6,'Paste Here'!$A:$A,'Paste Here'!E:E),0) -> 10026.023 | G6: =IFERROR(_xlfn.XLOOKUP($B6,'Paste Here'!$A:$A,'Paste Here'!F:F),0) -> 10575.209 | H6: =IFERROR(_xlfn.XLOOKUP($B6,'Paste Here'!$A:$A,'Paste Here'!G:G),0) -> 10369.806 | I6: =IFERROR(_xlfn.XLOOKUP($B6,'Paste Here'!$A:$A,'Paste Here'!H:H),0) -> 14672.4 | J6: =IFERROR(_xlfn.XLOOKUP($B6,'Paste Here'!$A:$A,'Paste Here'!I:I),0) -> 15349.058 | K6: =IFERROR(_xlfn.XLOOKUP($B6,'Paste Here'!$A:$A,'Paste Here'!J:J),0) -> 14353.114 | L6: =IFERROR(_xlfn.XLOOKUP($B6,'Paste Here'!$A:$A,'Paste Here'!K:K),0) -> 14978.464 | M6: =IFERROR(_xlfn.XLOOKUP($B6,'Paste Here'!$A:$A,'Paste Here'!L:L),0) -> 15395.957 | N6: =IFERROR(_xlfn.XLOOKUP($B6,'Paste Here'!$A:$A,'Paste Here'!M:M),0) -> 15299.085 | O6: =IFERROR(_xlfn.XLOOKUP($B6,'Paste Here'!$A:$A,'Paste Here'!N:N),0) -> 13189.965 | P6: =IFERROR(_xlfn.XLOOKUP($B6,'Paste Here'!$A:$A,'Paste Here'!O:O),0) -> 13246.09 | Q6: =IFERROR(_xlfn.XLOOKUP($B6,'Paste Here'!$A:$A,'Paste Here'!P:P),0) -> 11270.433 | R6: =IFERROR(_xlfn.XLOOKUP($B6,'Paste Here'!$A:$A,'Paste Here'!Q:Q),0) -> 13347.993 | S6: =IFERROR(_xlfn.XLOOKUP($B6,'Paste Here'!$A:$A,'Paste Here'!R:R),0) -> 9557.7072 | T6: =IFERROR(_xlfn.XLOOKUP($B6,'Paste Here'!$A:$A,'Paste Here'!S:S),0) -> 9005.6085 | U6: =IFERROR(_xlfn.XLOOKUP($B6,'Paste Here'!$A:$A,'Paste Here'!T:T),0) -> 10459.95 | V6: =IFERROR(_xlfn.XLOOKUP($B6,'Paste Here'!$A:$A,'Paste Here'!U:U),0) -> 12415.626 | W6: =IFERROR(_xlfn.XLOOKUP($B6,'Paste Here'!$A:$A,'Paste Here'!V:V),0) -> 12021.141 | X6: =IFERROR(_xlfn.XLOOKUP($B6,'Paste Here'!$A:$A,'Paste Here'!W:W),0) -> 12413.763 | Y6: =IFERROR(_xlfn.XLOOKUP($B6,'Paste Here'!$A:$A,'Paste Here'!X:X),0) -> 12822.596 | Z6: =IFERROR(_xlfn.XLOOKUP($B6,'Paste Here'!$A:$A,'Paste Here'!Y:Y),0) -> 13275.148 | AA6: =IFERROR(_xlfn.XLOOKUP($B6,'Paste Here'!$A:$A,'Paste Here'!Z:Z),0) -> 11291.124 | AB6: =IFERROR(_xlfn.XLOOKUP($B6,'Paste Here'!$A:$A,'Paste Here'!AA:AA),0) -> 10589.557 | AC6: =IFERROR(_xlfn.XLOOKUP($B6,'Paste Here'!$A:$A,'Paste Here'!AB:AB),0) -> 11731.237 | AD6: =IFERROR(_xlfn.XLOOKUP($B6,'Paste Here'!$A:$A,'Paste Here'!AC:AC),0) -> 14005.41 | AE6: =IFERROR(_xlfn.XLOOKUP($B6,'Paste Here'!$A:$A,'Paste Here'!AD:AD),0) -> 13519.747 | AF6: =IFERROR(_xlfn.XLOOKUP($B6,'Paste Here'!$A:$A,'Paste Here'!AE:AE),0) -> 12613.553 | AG6: =IFERROR(_xlfn.XLOOKUP($B6,'Paste Here'!$A:$A,'Paste Here'!AF:AF),0) -> 13414.414 | AH6: =IFERROR(_xlfn.XLOOKUP($B6,'Paste Here'!$A:$A,'Paste Here'!AG:AG),0) -> 12304.597
A7: SUP to DC excl. Transit (queue corr) | B7: Total DC In to Stock (Queue Corrected) | C7: =IFERROR(_xlfn.XLOOKUP($B7,'Paste Here'!$A:$A,'Paste Here'!B:B),0) -> 17464.036 | D7: =IFERROR(_xlfn.XLOOKUP($B7,'Paste Here'!$A:$A,'Paste Here'!C:C),0) -> 9095.21 | E7: =IFERROR(_xlfn.XLOOKUP($B7,'Paste Here'!$A:$A,'Paste Here'!D:D),0) -> 10503.364 | F7: =IFERROR(_xlfn.XLOOKUP($B7,'Paste Here'!$A:$A,'Paste Here'!E:E),0) -> 17607.023 | G7: =IFERROR(_xlfn.XLOOKUP($B7,'Paste Here'!$A:$A,'Paste Here'!F:F),0) -> 14166.209 | H7: =IFERROR(_xlfn.XLOOKUP($B7,'Paste Here'!$A:$A,'Paste Here'!G:G),0) -> 11395.806 | I7: =IFERROR(_xlfn.XLOOKUP($B7,'Paste Here'!$A:$A,'Paste Here'!H:H),0) -> 10691.36 | J7: =IFERROR(_xlfn.XLOOKUP($B7,'Paste Here'!$A:$A,'Paste Here'!I:I),0) -> 12591.412 | K7: =IFERROR(_xlfn.XLOOKUP($B7,'Paste Here'!$A:$A,'Paste Here'!J:J),0) -> 9816.4227 | L7: =IFERROR(_xlfn.XLOOKUP($B7,'Paste Here'!$A:$A,'Paste Here'!K:K),0) -> 11558.831 | M7: =IFERROR(_xlfn.XLOOKUP($B7,'Paste Here'!$A:$A,'Paste Here'!L:L),0) -> 12722.087 | N7: =IFERROR(_xlfn.XLOOKUP($B7,'Paste Here'!$A:$A,'Paste Here'!M:M),0) -> 12452.173 | O7: =IFERROR(_xlfn.XLOOKUP($B7,'Paste Here'!$A:$A,'Paste Here'!N:N),0) -> 10719.757 | P7: =IFERROR(_xlfn.XLOOKUP($B7,'Paste Here'!$A:$A,'Paste Here'!O:O),0) -> 13246.09 | Q7: =IFERROR(_xlfn.XLOOKUP($B7,'Paste Here'!$A:$A,'Paste Here'!P:P),0) -> 11270.433 | R7: =IFERROR(_xlfn.XLOOKUP($B7,'Paste Here'!$A:$A,'Paste Here'!Q:Q),0) -> 13347.993 | S7: =IFERROR(_xlfn.XLOOKUP($B7,'Paste Here'!$A:$A,'Paste Here'!R:R),0) -> 9557.7072 | T7: =IFERROR(_xlfn.XLOOKUP($B7,'Paste Here'!$A:$A,'Paste Here'!S:S),0) -> 9005.6085 | U7: =IFERROR(_xlfn.XLOOKUP($B7,'Paste Here'!$A:$A,'Paste Here'!T:T),0) -> 10459.95 | V7: =IFERROR(_xlfn.XLOOKUP($B7,'Paste Here'!$A:$A,'Paste Here'!U:U),0) -> 12415.626 | W7: =IFERROR(_xlfn.XLOOKUP($B7,'Paste Here'!$A:$A,'Paste Here'!V:V),0) -> 12021.141 | X7: =IFERROR(_xlfn.XLOOKUP($B7,'Paste Here'!$A:$A,'Paste Here'!W:W),0) -> 12413.763 | Y7: =IFERROR(_xlfn.XLOOKUP($B7,'Paste Here'!$A:$A,'Paste Here'!X:X),0) -> 12822.596 | Z7: =IFERROR(_xlfn.XLOOKUP($B7,'Paste Here'!$A:$A,'Paste Here'!Y:Y),0) -> 13275.148 | AA7: =IFERROR(_xlfn.XLOOKUP($B7,'Paste Here'!$A:$A,'Paste Here'!Z:Z),0) -> 11291.124 | AB7: =IFERROR(_xlfn.XLOOKUP($B7,'Paste Here'!$A:$A,'Paste Here'!AA:AA),0) -> 10589.557 | AC7: =IFERROR(_xlfn.XLOOKUP($B7,'Paste Here'!$A:$A,'Paste Here'!AB:AB),0) -> 11731.237 | AD7: =IFERROR(_xlfn.XLOOKUP($B7,'Paste Here'!$A:$A,'Paste Here'!AC:AC),0) -> 14005.41 | AE7: =IFERROR(_xlfn.XLOOKUP($B7,'Paste Here'!$A:$A,'Paste Here'!AD:AD),0) -> 13519.747 | AF7: =IFERROR(_xlfn.XLOOKUP($B7,'Paste Here'!$A:$A,'Paste Here'!AE:AE),0) -> 12613.553 | AG7: =IFERROR(_xlfn.XLOOKUP($B7,'Paste Here'!$A:$A,'Paste Here'!AF:AF),0) -> 13414.414 | AH7: =IFERROR(_xlfn.XLOOKUP($B7,'Paste Here'!$A:$A,'Paste Here'!AG:AG),0) -> 12304.597
A8: Other Inflow (clearings) | B8: DC In to Stock from other BU | C8: =IFERROR(_xlfn.XLOOKUP($B8,'Paste Here'!$A:$A,'Paste Here'!B:B),0) -> 191.422 | D8: =IFERROR(_xlfn.XLOOKUP($B8,'Paste Here'!$A:$A,'Paste Here'!C:C),0) -> 51.861 | E8: =IFERROR(_xlfn.XLOOKUP($B8,'Paste Here'!$A:$A,'Paste Here'!D:D),0) -> 0 | F8: =IFERROR(_xlfn.XLOOKUP($B8,'Paste Here'!$A:$A,'Paste Here'!E:E),0) -> 0 | G8: =IFERROR(_xlfn.XLOOKUP($B8,'Paste Here'!$A:$A,'Paste Here'!F:F),0) -> 0 | H8: =IFERROR(_xlfn.XLOOKUP($B8,'Paste Here'!$A:$A,'Paste Here'!G:G),0) -> 0.519 | I8: =IFERROR(_xlfn.XLOOKUP($B8,'Paste Here'!$A:$A,'Paste Here'!H:H),0) -> 5.271 | J8: =IFERROR(_xlfn.XLOOKUP($B8,'Paste Here'!$A:$A,'Paste Here'!I:I),0) -> 0 | K8: =IFERROR(_xlfn.XLOOKUP($B8,'Paste Here'!$A:$A,'Paste Here'!J:J),0) -> 0 | L8: =IFERROR(_xlfn.XLOOKUP($B8,'Paste Here'!$A:$A,'Paste Here'!K:K),0) -> 0 | M8: =IFERROR(_xlfn.XLOOKUP($B8,'Paste Here'!$A:$A,'Paste Here'!L:L),0) -> 0 | N8: =IFERROR(_xlfn.XLOOKUP($B8,'Paste Here'!$A:$A,'Paste Here'!M:M),0) -> 0 | O8: =IFERROR(_xlfn.XLOOKUP($B8,'Paste Here'!$A:$A,'Paste Here'!N:N),0) -> 0 | P8: =IFERROR(_xlfn.XLOOKUP($B8,'Paste Here'!$A:$A,'Paste Here'!O:O),0) -> 0 | Q8: =IFERROR(_xlfn.XLOOKUP($B8,'Paste Here'!$A:$A,'Paste Here'!P:P),0) -> 0 | R8: =IFERROR(_xlfn.XLOOKUP($B8,'Paste Here'!$A:$A,'Paste Here'!Q:Q),0) -> 0 | S8: =IFERROR(_xlfn.XLOOKUP($B8,'Paste Here'!$A:$A,'Paste Here'!R:R),0) -> 0 | T8: =IFERROR(_xlfn.XLOOKUP($B8,'Paste Here'!$A:$A,'Paste Here'!S:S),0) -> 0 | U8: =IFERROR(_xlfn.XLOOKUP($B8,'Paste Here'!$A:$A,'Paste Here'!T:T),0) -> 0 | V8: =IFERROR(_xlfn.XLOOKUP($B8,'Paste Here'!$A:$A,'Paste Here'!U:U),0) -> 0 | W8: =IFERROR(_xlfn.XLOOKUP($B8,'Paste Here'!$A:$A,'Paste Here'!V:V),0) -> 0 | X8: =IFERROR(_xlfn.XLOOKUP($B8,'Paste Here'!$A:$A,'Paste Here'!W:W),0) -> 0 | Y8: =IFERROR(_xlfn.XLOOKUP($B8,'Paste Here'!$A:$A,'Paste Here'!X:X),0) -> 0 | Z8: =IFERROR(_xlfn.XLOOKUP($B8,'Paste Here'!$A:$A,'Paste Here'!Y:Y),0) -> 0 | AA8: =IFERROR(_xlfn.XLOOKUP($B8,'Paste Here'!$A:$A,'Paste Here'!Z:Z),0) -> 0 | AB8: =IFERROR(_xlfn.XLOOKUP($B8,'Paste Here'!$A:$A,'Paste Here'!AA:AA),0) -> 0 | AC8: =IFERROR(_xlfn.XLOOKUP($B8,'Paste Here'!$A:$A,'Paste Here'!AB:AB),0) -> 0 | AD8: =IFERROR(_xlfn.XLOOKUP($B8,'Paste Here'!$A:$A,'Paste Here'!AC:AC),0) -> 0 | AE8: =IFERROR(_xlfn.XLOOKUP($B8,'Paste Here'!$A:$A,'Paste Here'!AD:AD),0) -> 0 | AF8: =IFERROR(_xlfn.XLOOKUP($B8,'Paste Here'!$A:$A,'Paste Here'!AE:AE),0) -> 0 | AG8: =IFERROR(_xlfn.XLOOKUP($B8,'Paste Here'!$A:$A,'Paste Here'!AF:AF),0) -> 0 | AH8: =IFERROR(_xlfn.XLOOKUP($B8,'Paste Here'!$A:$A,'Paste Here'!AG:AG),0) -> 0
A9: SUP to DC excl. Transit (queue corr) | B9: DC Replenishment and Other Inflow | C9: =IFERROR(_xlfn.XLOOKUP($B9,'Paste Here'!$A:$A,'Paste Here'!B:B),0) -> 17655.458 | D9: =IFERROR(_xlfn.XLOOKUP($B9,'Paste Here'!$A:$A,'Paste Here'!C:C),0) -> 9147.071 | E9: =IFERROR(_xlfn.XLOOKUP($B9,'Paste Here'!$A:$A,'Paste Here'!D:D),0) -> 10503.364 | F9: =IFERROR(_xlfn.XLOOKUP($B9,'Paste Here'!$A:$A,'Paste Here'!E:E),0) -> 17607.023 | G9: =IFERROR(_xlfn.XLOOKUP($B9,'Paste Here'!$A:$A,'Paste Here'!F:F),0) -> 14166.209 | H9: =IFERROR(_xlfn.XLOOKUP($B9,'Paste Here'!$A:$A,'Paste Here'!G:G),0) -> 11396.325 | I9: =IFERROR(_xlfn.XLOOKUP($B9,'Paste Here'!$A:$A,'Paste Here'!H:H),0) -> 10696.631 | J9: =IFERROR(_xlfn.XLOOKUP($B9,'Paste Here'!$A:$A,'Paste Here'!I:I),0) -> 12591.412 | K9: =IFERROR(_xlfn.XLOOKUP($B9,'Paste Here'!$A:$A,'Paste Here'!J:J),0) -> 9816.4227 | L9: =IFERROR(_xlfn.XLOOKUP($B9,'Paste Here'!$A:$A,'Paste Here'!K:K),0) -> 11558.831 | M9: =IFERROR(_xlfn.XLOOKUP($B9,'Paste Here'!$A:$A,'Paste Here'!L:L),0) -> 12722.087 | N9: =IFERROR(_xlfn.XLOOKUP($B9,'Paste Here'!$A:$A,'Paste Here'!M:M),0) -> 12452.173 | O9: =IFERROR(_xlfn.XLOOKUP($B9,'Paste Here'!$A:$A,'Paste Here'!N:N),0) -> 10719.757 | P9: =IFERROR(_xlfn.XLOOKUP($B9,'Paste Here'!$A:$A,'Paste Here'!O:O),0) -> 13246.09 | Q9: =IFERROR(_xlfn.XLOOKUP($B9,'Paste Here'!$A:$A,'Paste Here'!P:P),0) -> 11270.433 | R9: =IFERROR(_xlfn.XLOOKUP($B9,'Paste Here'!$A:$A,'Paste Here'!Q:Q),0) -> 13347.993 | S9: =IFERROR(_xlfn.XLOOKUP($B9,'Paste Here'!$A:$A,'Paste Here'!R:R),0) -> 9557.7072 | T9: =IFERROR(_xlfn.XLOOKUP($B9,'Paste Here'!$A:$A,'Paste Here'!S:S),0) -> 9005.6085 | U9: =IFERROR(_xlfn.XLOOKUP($B9,'Paste Here'!$A:$A,'Paste Here'!T:T),0) -> 10459.95 | V9: =IFERROR(_xlfn.XLOOKUP($B9,'Paste Here'!$A:$A,'Paste Here'!U:U),0) -> 12415.626 | W9: =IFERROR(_xlfn.XLOOKUP($B9,'Paste Here'!$A:$A,'Paste Here'!V:V),0) -> 12021.141 | X9: =IFERROR(_xlfn.XLOOKUP($B9,'Paste Here'!$A:$A,'Paste Here'!W:W),0) -> 12413.763 | Y9: =IFERROR(_xlfn.XLOOKUP($B9,'Paste Here'!$A:$A,'Paste Here'!X:X),0) -> 12822.596 | Z9: =IFERROR(_xlfn.XLOOKUP($B9,'Paste Here'!$A:$A,'Paste Here'!Y:Y),0) -> 13275.148 | AA9: =IFERROR(_xlfn.XLOOKUP($B9,'Paste Here'!$A:$A,'Paste Here'!Z:Z),0) -> 11291.124 | AB9: =IFERROR(_xlfn.XLOOKUP($B9,'Paste Here'!$A:$A,'Paste Here'!AA:AA),0) -> 10589.557 | AC9: =IFERROR(_xlfn.XLOOKUP($B9,'Paste Here'!$A:$A,'Paste Here'!AB:AB),0) -> 11731.237 | AD9: =IFERROR(_xlfn.XLOOKUP($B9,'Paste Here'!$A:$A,'Paste Here'!AC:AC),0) -> 14005.41 | AE9: =IFERROR(_xlfn.XLOOKUP($B9,'Paste Here'!$A:$A,'Paste Here'!AD:AD),0) -> 13519.747 | AF9: =IFERROR(_xlfn.XLOOKUP($B9,'Paste Here'!$A:$A,'Paste Here'!AE:AE),0) -> 12613.553 | AG9: =IFERROR(_xlfn.XLOOKUP($B9,'Paste Here'!$A:$A,'Paste Here'!AF:AF),0) -> 13414.414 | AH9: =IFERROR(_xlfn.XLOOKUP($B9,'Paste Here'!$A:$A,'Paste Here'!AG:AG),0) -> 12304.597
A10: Transit IN | B10: Total Transit IN | C10: =IFERROR(_xlfn.XLOOKUP($B10,'Paste Here'!$A:$A,'Paste Here'!B:B),0) -> 6489.953 | D10: =IFERROR(_xlfn.XLOOKUP($B10,'Paste Here'!$A:$A,'Paste Here'!C:C),0) -> 8016.13 | E10: =IFERROR(_xlfn.XLOOKUP($B10,'Paste Here'!$A:$A,'Paste Here'!D:D),0) -> 8413.51 | F10: =IFERROR(_xlfn.XLOOKUP($B10,'Paste Here'!$A:$A,'Paste Here'!E:E),0) -> 7785.01 | G10: =IFERROR(_xlfn.XLOOKUP($B10,'Paste Here'!$A:$A,'Paste Here'!F:F),0) -> 8503.834 | H10: =IFERROR(_xlfn.XLOOKUP($B10,'Paste Here'!$A:$A,'Paste Here'!G:G),0) -> 7333.47 | I10: =IFERROR(_xlfn.XLOOKUP($B10,'Paste Here'!$A:$A,'Paste Here'!H:H),0) -> 11180.797 | J10: =IFERROR(_xlfn.XLOOKUP($B10,'Paste Here'!$A:$A,'Paste Here'!I:I),0) -> 8371.813 | K10: =IFERROR(_xlfn.XLOOKUP($B10,'Paste Here'!$A:$A,'Paste Here'!J:J),0) -> 10117.606 | L10: =IFERROR(_xlfn.XLOOKUP($B10,'Paste Here'!$A:$A,'Paste Here'!K:K),0) -> 8669.836 | M10: =IFERROR(_xlfn.XLOOKUP($B10,'Paste Here'!$A:$A,'Paste Here'!L:L),0) -> 8260.056 | N10: =IFERROR(_xlfn.XLOOKUP($B10,'Paste Here'!$A:$A,'Paste Here'!M:M),0) -> 9513.43 | O10: =IFERROR(_xlfn.XLOOKUP($B10,'Paste Here'!$A:$A,'Paste Here'!N:N),0) -> 10133.84 | P10: =IFERROR(_xlfn.XLOOKUP($B10,'Paste Here'!$A:$A,'Paste Here'!O:O),0) -> 9543.5 | Q10: =IFERROR(_xlfn.XLOOKUP($B10,'Paste Here'!$A:$A,'Paste Here'!P:P),0) -> 9795 | R10: =IFERROR(_xlfn.XLOOKUP($B10,'Paste Here'!$A:$A,'Paste Here'!Q:Q),0) -> 9766.62 | S10: =IFERROR(_xlfn.XLOOKUP($B10,'Paste Here'!$A:$A,'Paste Here'!R:R),0) -> 9361.33 | T10: =IFERROR(_xlfn.XLOOKUP($B10,'Paste Here'!$A:$A,'Paste Here'!S:S),0) -> 9499.2 | U10: =IFERROR(_xlfn.XLOOKUP($B10,'Paste Here'!$A:$A,'Paste Here'!T:T),0) -> 9012.3 | V10: =IFERROR(_xlfn.XLOOKUP($B10,'Paste Here'!$A:$A,'Paste Here'!U:U),0) -> 7789.93 | W10: =IFERROR(_xlfn.XLOOKUP($B10,'Paste Here'!$A:$A,'Paste Here'!V:V),0) -> 7887.95 | X10: =IFERROR(_xlfn.XLOOKUP($B10,'Paste Here'!$A:$A,'Paste Here'!W:W),0) -> 9269.71 | Y10: =IFERROR(_xlfn.XLOOKUP($B10,'Paste Here'!$A:$A,'Paste Here'!X:X),0) -> 9218.44 | Z10: =IFERROR(_xlfn.XLOOKUP($B10,'Paste Here'!$A:$A,'Paste Here'!Y:Y),0) -> 9113.91 | AA10: =IFERROR(_xlfn.XLOOKUP($B10,'Paste Here'!$A:$A,'Paste Here'!Z:Z),0) -> 5638.46 | AB10: =IFERROR(_xlfn.XLOOKUP($B10,'Paste Here'!$A:$A,'Paste Here'!AA:AA),0) -> 6800.35 | AC10: =IFERROR(_xlfn.XLOOKUP($B10,'Paste Here'!$A:$A,'Paste Here'!AB:AB),0) -> 8111.14 | AD10: =IFERROR(_xlfn.XLOOKUP($B10,'Paste Here'!$A:$A,'Paste Here'!AC:AC),0) -> 8464.46 | AE10: =IFERROR(_xlfn.XLOOKUP($B10,'Paste Here'!$A:$A,'Paste Here'!AD:AD),0) -> 8640.17 | AF10: =IFERROR(_xlfn.XLOOKUP($B10,'Paste Here'!$A:$A,'Paste Here'!AE:AE),0) -> 8750.52 | AG10: =IFERROR(_xlfn.XLOOKUP($B10,'Paste Here'!$A:$A,'Paste Here'!AF:AF),0) -> 9396.13 | AH10: =IFERROR(_xlfn.XLOOKUP($B10,'Paste Here'!$A:$A,'Paste Here'!AG:AG),0) -> 8209.99
B11: Total Inflow | C11: =IFERROR(_xlfn.XLOOKUP($B11,'Paste Here'!$A:$A,'Paste Here'!B:B),0) -> 19129.411 | D11: =IFERROR(_xlfn.XLOOKUP($B11,'Paste Here'!$A:$A,'Paste Here'!C:C),0) -> 19785.201 | E11: =IFERROR(_xlfn.XLOOKUP($B11,'Paste Here'!$A:$A,'Paste Here'!D:D),0) -> 18688.874 | F11: =IFERROR(_xlfn.XLOOKUP($B11,'Paste Here'!$A:$A,'Paste Here'!E:E),0) -> 17811.033 | G11: =IFERROR(_xlfn.XLOOKUP($B11,'Paste Here'!$A:$A,'Paste Here'!F:F),0) -> 19079.043 | H11: =IFERROR(_xlfn.XLOOKUP($B11,'Paste Here'!$A:$A,'Paste Here'!G:G),0) -> 17703.795 | I11: =IFERROR(_xlfn.XLOOKUP($B11,'Paste Here'!$A:$A,'Paste Here'!H:H),0) -> 25858.468 | J11: =IFERROR(_xlfn.XLOOKUP($B11,'Paste Here'!$A:$A,'Paste Here'!I:I),0) -> 23720.871 | K11: =IFERROR(_xlfn.XLOOKUP($B11,'Paste Here'!$A:$A,'Paste Here'!J:J),0) -> 24470.72 | L11: =IFERROR(_xlfn.XLOOKUP($B11,'Paste Here'!$A:$A,'Paste Here'!K:K),0) -> 23648.3 | M11: =IFERROR(_xlfn.XLOOKUP($B11,'Paste Here'!$A:$A,'Paste Here'!L:L),0) -> 23656.013 | N11: =IFERROR(_xlfn.XLOOKUP($B11,'Paste Here'!$A:$A,'Paste Here'!M:M),0) -> 24812.515 | O11: =IFERROR(_xlfn.XLOOKUP($B11,'Paste Here'!$A:$A,'Paste Here'!N:N),0) -> 23323.805 | P11: =IFERROR(_xlfn.XLOOKUP($B11,'Paste Here'!$A:$A,'Paste Here'!O:O),0) -> 22789.59 | Q11: =IFERROR(_xlfn.XLOOKUP($B11,'Paste Here'!$A:$A,'Paste Here'!P:P),0) -> 21065.433 | R11: =IFERROR(_xlfn.XLOOKUP($B11,'Paste Here'!$A:$A,'Paste Here'!Q:Q),0) -> 23114.613 | S11: =IFERROR(_xlfn.XLOOKUP($B11,'Paste Here'!$A:$A,'Paste Here'!R:R),0) -> 18919.037 | T11: =IFERROR(_xlfn.XLOOKUP($B11,'Paste Here'!$A:$A,'Paste Here'!S:S),0) -> 18504.808 | U11: =IFERROR(_xlfn.XLOOKUP($B11,'Paste Here'!$A:$A,'Paste Here'!T:T),0) -> 19472.25 | V11: =IFERROR(_xlfn.XLOOKUP($B11,'Paste Here'!$A:$A,'Paste Here'!U:U),0) -> 20205.556 | W11: =IFERROR(_xlfn.XLOOKUP($B11,'Paste Here'!$A:$A,'Paste Here'!V:V),0) -> 19909.091 | X11: =IFERROR(_xlfn.XLOOKUP($B11,'Paste Here'!$A:$A,'Paste Here'!W:W),0) -> 21683.473 | Y11: =IFERROR(_xlfn.XLOOKUP($B11,'Paste Here'!$A:$A,'Paste Here'!X:X),0) -> 22041.036 | Z11: =IFERROR(_xlfn.XLOOKUP($B11,'Paste Here'!$A:$A,'Paste Here'!Y:Y),0) -> 22389.058 | AA11: =IFERROR(_xlfn.XLOOKUP($B11,'Paste Here'!$A:$A,'Paste Here'!Z:Z),0) -> 16929.584 | AB11: =IFERROR(_xlfn.XLOOKUP($B11,'Paste Here'!$A:$A,'Paste Here'!AA:AA),0) -> 17389.907 | AC11: =IFERROR(_xlfn.XLOOKUP($B11,'Paste Here'!$A:$A,'Paste Here'!AB:AB),0) -> 19842.377 | AD11: =IFERROR(_xlfn.XLOOKUP($B11,'Paste Here'!$A:$A,'Paste Here'!AC:AC),0) -> 22469.87 | AE11: =IFERROR(_xlfn.XLOOKUP($B11,'Paste Here'!$A:$A,'Paste Here'!AD:AD),0) -> 22159.917 | AF11: =IFERROR(_xlfn.XLOOKUP($B11,'Paste Here'!$A:$A,'Paste Here'!AE:AE),0) -> 21364.073 | AG11: =IFERROR(_xlfn.XLOOKUP($B11,'Paste Here'!$A:$A,'Paste Here'!AF:AF),0) -> 22810.544 | AH11: =IFERROR(_xlfn.XLOOKUP($B11,'Paste Here'!$A:$A,'Paste Here'!AG:AG),0) -> 20514.587
A12: TOTAL INFLOW (queue corr) | B12: Total Inflow (Queue Corrected) | C12: =IFERROR(_xlfn.XLOOKUP($B12,'Paste Here'!$A:$A,'Paste Here'!B:B),0) -> 24145.411 | D12: =IFERROR(_xlfn.XLOOKUP($B12,'Paste Here'!$A:$A,'Paste Here'!C:C),0) -> 17163.201 | E12: =IFERROR(_xlfn.XLOOKUP($B12,'Paste Here'!$A:$A,'Paste Here'!D:D),0) -> 18916.874 | F12: =IFERROR(_xlfn.XLOOKUP($B12,'Paste Here'!$A:$A,'Paste Here'!E:E),0) -> 25392.033 | G12: =IFERROR(_xlfn.XLOOKUP($B12,'Paste Here'!$A:$A,'Paste Here'!F:F),0) -> 22670.043 | H12: =IFERROR(_xlfn.XLOOKUP($B12,'Paste Here'!$A:$A,'Paste Here'!G:G),0) -> 18729.795 | I12: =IFERROR(_xlfn.XLOOKUP($B12,'Paste Here'!$A:$A,'Paste Here'!H:H),0) -> 21877.428 | J12: =IFERROR(_xlfn.XLOOKUP($B12,'Paste Here'!$A:$A,'Paste Here'!I:I),0) -> 20963.225 | K12: =IFERROR(_xlfn.XLOOKUP($B12,'Paste Here'!$A:$A,'Paste Here'!J:J),0) -> 19934.029 | L12: =IFERROR(_xlfn.XLOOKUP($B12,'Paste Here'!$A:$A,'Paste Here'!K:K),0) -> 20228.667 | M12: =IFERROR(_xlfn.XLOOKUP($B12,'Paste Here'!$A:$A,'Paste Here'!L:L),0) -> 20982.143 | N12: =IFERROR(_xlfn.XLOOKUP($B12,'Paste Here'!$A:$A,'Paste Here'!M:M),0) -> 21965.603 | O12: =IFERROR(_xlfn.XLOOKUP($B12,'Paste Here'!$A:$A,'Paste Here'!N:N),0) -> 20853.597 | P12: =IFERROR(_xlfn.XLOOKUP($B12,'Paste Here'!$A:$A,'Paste Here'!O:O),0) -> 22789.59 | Q12: =IFERROR(_xlfn.XLOOKUP($B12,'Paste Here'!$A:$A,'Paste Here'!P:P),0) -> 21065.433 | R12: =IFERROR(_xlfn.XLOOKUP($B12,'Paste Here'!$A:$A,'Paste Here'!Q:Q),0) -> 23114.613 | S12: =IFERROR(_xlfn.XLOOKUP($B12,'Paste Here'!$A:$A,'Paste Here'!R:R),0) -> 18919.037 | T12: =IFERROR(_xlfn.XLOOKUP($B12,'Paste Here'!$A:$A,'Paste Here'!S:S),0) -> 18504.808 | U12: =IFERROR(_xlfn.XLOOKUP($B12,'Paste Here'!$A:$A,'Paste Here'!T:T),0) -> 19472.25 | V12: =IFERROR(_xlfn.XLOOKUP($B12,'Paste Here'!$A:$A,'Paste Here'!U:U),0) -> 20205.556 | W12: =IFERROR(_xlfn.XLOOKUP($B12,'Paste Here'!$A:$A,'Paste Here'!V:V),0) -> 19909.091 | X12: =IFERROR(_xlfn.XLOOKUP($B12,'Paste Here'!$A:$A,'Paste Here'!W:W),0) -> 21683.473 | Y12: =IFERROR(_xlfn.XLOOKUP($B12,'Paste Here'!$A:$A,'Paste Here'!X:X),0) -> 22041.036 | Z12: =IFERROR(_xlfn.XLOOKUP($B12,'Paste Here'!$A:$A,'Paste Here'!Y:Y),0) -> 22389.058 | AA12: =IFERROR(_xlfn.XLOOKUP($B12,'Paste Here'!$A:$A,'Paste Here'!Z:Z),0) -> 16929.584 | AB12: =IFERROR(_xlfn.XLOOKUP($B12,'Paste Here'!$A:$A,'Paste Here'!AA:AA),0) -> 17389.907 | AC12: =IFERROR(_xlfn.XLOOKUP($B12,'Paste Here'!$A:$A,'Paste Here'!AB:AB),0) -> 19842.377 | AD12: =IFERROR(_xlfn.XLOOKUP($B12,'Paste Here'!$A:$A,'Paste Here'!AC:AC),0) -> 22469.87 | AE12: =IFERROR(_xlfn.XLOOKUP($B12,'Paste Here'!$A:$A,'Paste Here'!AD:AD),0) -> 22159.917 | AF12: =IFERROR(_xlfn.XLOOKUP($B12,'Paste Here'!$A:$A,'Paste Here'!AE:AE),0) -> 21364.073 | AG12: =IFERROR(_xlfn.XLOOKUP($B12,'Paste Here'!$A:$A,'Paste Here'!AF:AF),0) -> 22810.544 | AH12: =IFERROR(_xlfn.XLOOKUP($B12,'Paste Here'!$A:$A,'Paste Here'!AG:AG),0) -> 20514.587
B13: Land Volume (DC Stock) | C13: =IFERROR(_xlfn.XLOOKUP($B13,'Paste Here'!$A:$A,'Paste Here'!B:B),0) -> 4918.005 | D13: =IFERROR(_xlfn.XLOOKUP($B13,'Paste Here'!$A:$A,'Paste Here'!C:C),0) -> 4182.286 | E13: =IFERROR(_xlfn.XLOOKUP($B13,'Paste Here'!$A:$A,'Paste Here'!D:D),0) -> 4576.384 | F13: =IFERROR(_xlfn.XLOOKUP($B13,'Paste Here'!$A:$A,'Paste Here'!E:E),0) -> 4214.885 | G13: =IFERROR(_xlfn.XLOOKUP($B13,'Paste Here'!$A:$A,'Paste Here'!F:F),0) -> 4870.572 | H13: =IFERROR(_xlfn.XLOOKUP($B13,'Paste Here'!$A:$A,'Paste Here'!G:G),0) -> 4541.383 | I13: =IFERROR(_xlfn.XLOOKUP($B13,'Paste Here'!$A:$A,'Paste Here'!H:H),0) -> 3837.1293 | J13: =IFERROR(_xlfn.XLOOKUP($B13,'Paste Here'!$A:$A,'Paste Here'!I:I),0) -> 4519.0577 | K13: =IFERROR(_xlfn.XLOOKUP($B13,'Paste Here'!$A:$A,'Paste Here'!J:J),0) -> 3523.1141 | L13: =IFERROR(_xlfn.XLOOKUP($B13,'Paste Here'!$A:$A,'Paste Here'!K:K),0) -> 4148.4644 | M13: =IFERROR(_xlfn.XLOOKUP($B13,'Paste Here'!$A:$A,'Paste Here'!L:L),0) -> 4565.957 | N13: =IFERROR(_xlfn.XLOOKUP($B13,'Paste Here'!$A:$A,'Paste Here'!M:M),0) -> 4469.085 | O13: =IFERROR(_xlfn.XLOOKUP($B13,'Paste Here'!$A:$A,'Paste Here'!N:N),0) -> 3847.321 | P13: =IFERROR(_xlfn.XLOOKUP($B13,'Paste Here'!$A:$A,'Paste Here'!O:O),0) -> 4754.0217 | Q13: =IFERROR(_xlfn.XLOOKUP($B13,'Paste Here'!$A:$A,'Paste Here'!P:P),0) -> 4044.9585 | R13: =IFERROR(_xlfn.XLOOKUP($B13,'Paste Here'!$A:$A,'Paste Here'!Q:Q),0) -> 4790.5945 | S13: =IFERROR(_xlfn.XLOOKUP($B13,'Paste Here'!$A:$A,'Paste Here'!R:R),0) -> 3430.2611 | T13: =IFERROR(_xlfn.XLOOKUP($B13,'Paste Here'!$A:$A,'Paste Here'!S:S),0) -> 3232.1129 | U13: =IFERROR(_xlfn.XLOOKUP($B13,'Paste Here'!$A:$A,'Paste Here'!T:T),0) -> 3754.0762 | V13: =IFERROR(_xlfn.XLOOKUP($B13,'Paste Here'!$A:$A,'Paste Here'!U:U),0) -> 4455.9683 | W13: =IFERROR(_xlfn.XLOOKUP($B13,'Paste Here'!$A:$A,'Paste Here'!V:V),0) -> 4314.3876 | X13: =IFERROR(_xlfn.XLOOKUP($B13,'Paste Here'!$A:$A,'Paste Here'!W:W),0) -> 4455.2996 | Y13: =IFERROR(_xlfn.XLOOKUP($B13,'Paste Here'!$A:$A,'Paste Here'!X:X),0) -> 4602.0298 | Z13: =IFERROR(_xlfn.XLOOKUP($B13,'Paste Here'!$A:$A,'Paste Here'!Y:Y),0) -> 4764.4505 | AA13: =IFERROR(_xlfn.XLOOKUP($B13,'Paste Here'!$A:$A,'Paste Here'!Z:Z),0) -> 4052.3846 | AB13: =IFERROR(_xlfn.XLOOKUP($B13,'Paste Here'!$A:$A,'Paste Here'!AA:AA),0) -> 3800.592 | AC13: =IFERROR(_xlfn.XLOOKUP($B13,'Paste Here'!$A:$A,'Paste Here'!AB:AB),0) -> 4210.3411 | AD13: =IFERROR(_xlfn.XLOOKUP($B13,'Paste Here'!$A:$A,'Paste Here'!AC:AC),0) -> 5026.5417 | AE13: =IFERROR(_xlfn.XLOOKUP($B13,'Paste Here'!$A:$A,'Paste Here'!AD:AD),0) -> 4852.237 | AF13: =IFERROR(_xlfn.XLOOKUP($B13,'Paste Here'!$A:$A,'Paste Here'!AE:AE),0) -> 4527.0042 | AG13: =IFERROR(_xlfn.XLOOKUP($B13,'Paste Here'!$A:$A,'Paste Here'!AF:AF),0) -> 4814.433 | AH13: =IFERROR(_xlfn.XLOOKUP($B13,'Paste Here'!$A:$A,'Paste Here'!AG:AG),0) -> 4416.1199
A14: DC to Store (excl. Transit) | B14: Land Volume (Transit) | C14: =IFERROR(_xlfn.XLOOKUP($B14,'Paste Here'!$A:$A,'Paste Here'!B:B),0) -> 6489.953 | D14: =IFERROR(_xlfn.XLOOKUP($B14,'Paste Here'!$A:$A,'Paste Here'!C:C),0) -> 8016.13 | E14: =IFERROR(_xlfn.XLOOKUP($B14,'Paste Here'!$A:$A,'Paste Here'!D:D),0) -> 8413.51 | F14: =IFERROR(_xlfn.XLOOKUP($B14,'Paste Here'!$A:$A,'Paste Here'!E:E),0) -> 7785.01 | G14: =IFERROR(_xlfn.XLOOKUP($B14,'Paste Here'!$A:$A,'Paste Here'!F:F),0) -> 8503.834 | H14: =IFERROR(_xlfn.XLOOKUP($B14,'Paste Here'!$A:$A,'Paste Here'!G:G),0) -> 7333.47 | I14: =IFERROR(_xlfn.XLOOKUP($B14,'Paste Here'!$A:$A,'Paste Here'!H:H),0) -> 11180.797 | J14: =IFERROR(_xlfn.XLOOKUP($B14,'Paste Here'!$A:$A,'Paste Here'!I:I),0) -> 8371.813 | K14: =IFERROR(_xlfn.XLOOKUP($B14,'Paste Here'!$A:$A,'Paste Here'!J:J),0) -> 10117.606 | L14: =IFERROR(_xlfn.XLOOKUP($B14,'Paste Here'!$A:$A,'Paste Here'!K:K),0) -> 8669.836 | M14: =IFERROR(_xlfn.XLOOKUP($B14,'Paste Here'!$A:$A,'Paste Here'!L:L),0) -> 8260.056 | N14: =IFERROR(_xlfn.XLOOKUP($B14,'Paste Here'!$A:$A,'Paste Here'!M:M),0) -> 9513.43 | O14: =IFERROR(_xlfn.XLOOKUP($B14,'Paste Here'!$A:$A,'Paste Here'!N:N),0) -> 10133.84 | P14: =IFERROR(_xlfn.XLOOKUP($B14,'Paste Here'!$A:$A,'Paste Here'!O:O),0) -> 9543.5 | Q14: =IFERROR(_xlfn.XLOOKUP($B14,'Paste Here'!$A:$A,'Paste Here'!P:P),0) -> 9795 | R14: =IFERROR(_xlfn.XLOOKUP($B14,'Paste Here'!$A:$A,'Paste Here'!Q:Q),0) -> 9766.62 | S14: =IFERROR(_xlfn.XLOOKUP($B14,'Paste Here'!$A:$A,'Paste Here'!R:R),0) -> 9361.33 | T14: =IFERROR(_xlfn.XLOOKUP($B14,'Paste Here'!$A:$A,'Paste Here'!S:S),0) -> 9499.2 | U14: =IFERROR(_xlfn.XLOOKUP($B14,'Paste Here'!$A:$A,'Paste Here'!T:T),0) -> 9012.3 | V14: =IFERROR(_xlfn.XLOOKUP($B14,'Paste Here'!$A:$A,'Paste Here'!U:U),0) -> 7789.93 | W14: =IFERROR(_xlfn.XLOOKUP($B14,'Paste Here'!$A:$A,'Paste Here'!V:V),0) -> 7887.95 | X14: =IFERROR(_xlfn.XLOOKUP($B14,'Paste Here'!$A:$A,'Paste Here'!W:W),0) -> 9269.71 | Y14: =IFERROR(_xlfn.XLOOKUP($B14,'Paste Here'!$A:$A,'Paste Here'!X:X),0) -> 9218.44 | Z14: =IFERROR(_xlfn.XLOOKUP($B14,'Paste Here'!$A:$A,'Paste Here'!Y:Y),0) -> 9113.91 | AA14: =IFERROR(_xlfn.XLOOKUP($B14,'Paste Here'!$A:$A,'Paste Here'!Z:Z),0) -> 5638.46 | AB14: =IFERROR(_xlfn.XLOOKUP($B14,'Paste Here'!$A:$A,'Paste Here'!AA:AA),0) -> 6800.35 | AC14: =IFERROR(_xlfn.XLOOKUP($B14,'Paste Here'!$A:$A,'Paste Here'!AB:AB),0) -> 8111.14 | AD14: =IFERROR(_xlfn.XLOOKUP($B14,'Paste Here'!$A:$A,'Paste Here'!AC:AC),0) -> 8464.46 | AE14: =IFERROR(_xlfn.XLOOKUP($B14,'Paste Here'!$A:$A,'Paste Here'!AD:AD),0) -> 8640.17 | AF14: =IFERROR(_xlfn.XLOOKUP($B14,'Paste Here'!$A:$A,'Paste Here'!AE:AE),0) -> 8750.52 | AG14: =IFERROR(_xlfn.XLOOKUP($B14,'Paste Here'!$A:$A,'Paste Here'!AF:AF),0) -> 9396.13 | AH14: =IFERROR(_xlfn.XLOOKUP($B14,'Paste Here'!$A:$A,'Paste Here'!AG:AG),0) -> 8209.99
A15: DC to CDC | B15: Ocean Volume (DC Stock) | C15: =IFERROR(_xlfn.XLOOKUP($B15,'Paste Here'!$A:$A,'Paste Here'!B:B),0) -> 12737.453 | D15: =IFERROR(_xlfn.XLOOKUP($B15,'Paste Here'!$A:$A,'Paste Here'!C:C),0) -> 4964.785 | E15: =IFERROR(_xlfn.XLOOKUP($B15,'Paste Here'!$A:$A,'Paste Here'!D:D),0) -> 5926.98 | F15: =IFERROR(_xlfn.XLOOKUP($B15,'Paste Here'!$A:$A,'Paste Here'!E:E),0) -> 13392.138 | G15: =IFERROR(_xlfn.XLOOKUP($B15,'Paste Here'!$A:$A,'Paste Here'!F:F),0) -> 9295.637 | H15: =IFERROR(_xlfn.XLOOKUP($B15,'Paste Here'!$A:$A,'Paste Here'!G:G),0) -> 6854.942 | I15: =IFERROR(_xlfn.XLOOKUP($B15,'Paste Here'!$A:$A,'Paste Here'!H:H),0) -> 6854.2312 | J15: =IFERROR(_xlfn.XLOOKUP($B15,'Paste Here'!$A:$A,'Paste Here'!I:I),0) -> 8072.3542 | K15: =IFERROR(_xlfn.XLOOKUP($B15,'Paste Here'!$A:$A,'Paste Here'!J:J),0) -> 6293.3086 | L15: =IFERROR(_xlfn.XLOOKUP($B15,'Paste Here'!$A:$A,'Paste Here'!K:K),0) -> 7410.3665 | M15: =IFERROR(_xlfn.XLOOKUP($B15,'Paste Here'!$A:$A,'Paste Here'!L:L),0) -> 8156.1299 | N15: =IFERROR(_xlfn.XLOOKUP($B15,'Paste Here'!$A:$A,'Paste Here'!M:M),0) -> 7983.0882 | O15: =IFERROR(_xlfn.XLOOKUP($B15,'Paste Here'!$A:$A,'Paste Here'!N:N),0) -> 6872.4365 | P15: =IFERROR(_xlfn.XLOOKUP($B15,'Paste Here'!$A:$A,'Paste Here'!O:O),0) -> 8492.0683 | Q15: =IFERROR(_xlfn.XLOOKUP($B15,'Paste Here'!$A:$A,'Paste Here'!P:P),0) -> 7225.4748 | R15: =IFERROR(_xlfn.XLOOKUP($B15,'Paste Here'!$A:$A,'Paste Here'!Q:Q),0) -> 8557.3981 | S15: =IFERROR(_xlfn.XLOOKUP($B15,'Paste Here'!$A:$A,'Paste Here'!R:R),0) -> 6127.4461 | T15: =IFERROR(_xlfn.XLOOKUP($B15,'Paste Here'!$A:$A,'Paste Here'!S:S),0) -> 5773.4956 | U15: =IFERROR(_xlfn.XLOOKUP($B15,'Paste Here'!$A:$A,'Paste Here'!T:T),0) -> 6705.8742 | V15: =IFERROR(_xlfn.XLOOKUP($B15,'Paste Here'!$A:$A,'Paste Here'!U:U),0) -> 7959.6581 | W15: =IFERROR(_xlfn.XLOOKUP($B15,'Paste Here'!$A:$A,'Paste Here'!V:V),0) -> 7706.7536 | X15: =IFERROR(_xlfn.XLOOKUP($B15,'Paste Here'!$A:$A,'Paste Here'!W:W),0) -> 7958.4635 | Y15: =IFERROR(_xlfn.XLOOKUP($B15,'Paste Here'!$A:$A,'Paste Here'!X:X),0) -> 8220.5665 | Z15: =IFERROR(_xlfn.XLOOKUP($B15,'Paste Here'!$A:$A,'Paste Here'!Y:Y),0) -> 8510.6972 | AA15: =IFERROR(_xlfn.XLOOKUP($B15,'Paste Here'!$A:$A,'Paste Here'!Z:Z),0) -> 7238.7399 | AB15: =IFERROR(_xlfn.XLOOKUP($B15,'Paste Here'!$A:$A,'Paste Here'!AA:AA),0) -> 6788.965 | AC15: =IFERROR(_xlfn.XLOOKUP($B15,'Paste Here'!$A:$A,'Paste Here'!AB:AB),0) -> 7520.8962 | AD15: =IFERROR(_xlfn.XLOOKUP($B15,'Paste Here'!$A:$A,'Paste Here'!AC:AC),0) -> 8978.8684 | AE15: =IFERROR(_xlfn.XLOOKUP($B15,'Paste Here'!$A:$A,'Paste Here'!AD:AD),0) -> 8667.5095 | AF15: =IFERROR(_xlfn.XLOOKUP($B15,'Paste Here'!$A:$A,'Paste Here'!AE:AE),0) -> 8086.5489 | AG15: =IFERROR(_xlfn.XLOOKUP($B15,'Paste Here'!$A:$A,'Paste Here'!AF:AF),0) -> 8599.9805 | AH15: =IFERROR(_xlfn.XLOOKUP($B15,'Paste Here'!$A:$A,'Paste Here'!AG:AG),0) -> 7888.4772
A16: Other Outflow (clearings) | B16: Ocean Volume (Transit) | C16: =IFERROR(_xlfn.XLOOKUP($B16,'Paste Here'!$A:$A,'Paste Here'!B:B),0) -> 0 | D16: =IFERROR(_xlfn.XLOOKUP($B16,'Paste Here'!$A:$A,'Paste Here'!C:C),0) -> 0 | E16: =IFERROR(_xlfn.XLOOKUP($B16,'Paste Here'!$A:$A,'Paste Here'!D:D),0) -> 0 | F16: =IFERROR(_xlfn.XLOOKUP($B16,'Paste Here'!$A:$A,'Paste Here'!E:E),0) -> 0 | G16: =IFERROR(_xlfn.XLOOKUP($B16,'Paste Here'!$A:$A,'Paste Here'!F:F),0) -> 0 | H16: =IFERROR(_xlfn.XLOOKUP($B16,'Paste Here'!$A:$A,'Paste Here'!G:G),0) -> 0 | I16: =IFERROR(_xlfn.XLOOKUP($B16,'Paste Here'!$A:$A,'Paste Here'!H:H),0) -> 0 | J16: =IFERROR(_xlfn.XLOOKUP($B16,'Paste Here'!$A:$A,'Paste Here'!I:I),0) -> 0 | K16: =IFERROR(_xlfn.XLOOKUP($B16,'Paste Here'!$A:$A,'Paste Here'!J:J),0) -> 0 | L16: =IFERROR(_xlfn.XLOOKUP($B16,'Paste Here'!$A:$A,'Paste Here'!K:K),0) -> 0 | M16: =IFERROR(_xlfn.XLOOKUP($B16,'Paste Here'!$A:$A,'Paste Here'!L:L),0) -> 0 | N16: =IFERROR(_xlfn.XLOOKUP($B16,'Paste Here'!$A:$A,'Paste Here'!M:M),0) -> 0 | O16: =IFERROR(_xlfn.XLOOKUP($B16,'Paste Here'!$A:$A,'Paste Here'!N:N),0) -> 0 | P16: =IFERROR(_xlfn.XLOOKUP($B16,'Paste Here'!$A:$A,'Paste Here'!O:O),0) -> 0 | Q16: =IFERROR(_xlfn.XLOOKUP($B16,'Paste Here'!$A:$A,'Paste Here'!P:P),0) -> 0 | R16: =IFERROR(_xlfn.XLOOKUP($B16,'Paste Here'!$A:$A,'Paste Here'!Q:Q),0) -> 0 | S16: =IFERROR(_xlfn.XLOOKUP($B16,'Paste Here'!$A:$A,'Paste Here'!R:R),0) -> 0 | T16: =IFERROR(_xlfn.XLOOKUP($B16,'Paste Here'!$A:$A,'Paste Here'!S:S),0) -> 0 | U16: =IFERROR(_xlfn.XLOOKUP($B16,'Paste Here'!$A:$A,'Paste Here'!T:T),0) -> 0 | V16: =IFERROR(_xlfn.XLOOKUP($B16,'Paste Here'!$A:$A,'Paste Here'!U:U),0) -> 0 | W16: =IFERROR(_xlfn.XLOOKUP($B16,'Paste Here'!$A:$A,'Paste Here'!V:V),0) -> 0 | X16: =IFERROR(_xlfn.XLOOKUP($B16,'Paste Here'!$A:$A,'Paste Here'!W:W),0) -> 0 | Y16: =IFERROR(_xlfn.XLOOKUP($B16,'Paste Here'!$A:$A,'Paste Here'!X:X),0) -> 0 | Z16: =IFERROR(_xlfn.XLOOKUP($B16,'Paste Here'!$A:$A,'Paste Here'!Y:Y),0) -> 0 | AA16: =IFERROR(_xlfn.XLOOKUP($B16,'Paste Here'!$A:$A,'Paste Here'!Z:Z),0) -> 0 | AB16: =IFERROR(_xlfn.XLOOKUP($B16,'Paste Here'!$A:$A,'Paste Here'!AA:AA),0) -> 0 | AC16: =IFERROR(_xlfn.XLOOKUP($B16,'Paste Here'!$A:$A,'Paste Here'!AB:AB),0) -> 0 | AD16: =IFERROR(_xlfn.XLOOKUP($B16,'Paste Here'!$A:$A,'Paste Here'!AC:AC),0) -> 0 | AE16: =IFERROR(_xlfn.XLOOKUP($B16,'Paste Here'!$A:$A,'Paste Here'!AD:AD),0) -> 0 | AF16: =IFERROR(_xlfn.XLOOKUP($B16,'Paste Here'!$A:$A,'Paste Here'!AE:AE),0) -> 0 | AG16: =IFERROR(_xlfn.XLOOKUP($B16,'Paste Here'!$A:$A,'Paste Here'!AF:AF),0) -> 0 | AH16: =IFERROR(_xlfn.XLOOKUP($B16,'Paste Here'!$A:$A,'Paste Here'!AG:AG),0) -> 0
B17: - | C17: =IFERROR(_xlfn.XLOOKUP($B17,'Paste Here'!$A:$A,'Paste Here'!B:B),0) -> 0 | D17: =IFERROR(_xlfn.XLOOKUP($B17,'Paste Here'!$A:$A,'Paste Here'!C:C),0) -> 0 | E17: =IFERROR(_xlfn.XLOOKUP($B17,'Paste Here'!$A:$A,'Paste Here'!D:D),0) -> 0 | F17: =IFERROR(_xlfn.XLOOKUP($B17,'Paste Here'!$A:$A,'Paste Here'!E:E),0) -> 0 | G17: =IFERROR(_xlfn.XLOOKUP($B17,'Paste Here'!$A:$A,'Paste Here'!F:F),0) -> 0 | H17: =IFERROR(_xlfn.XLOOKUP($B17,'Paste Here'!$A:$A,'Paste Here'!G:G),0) -> 0 | I17: =IFERROR(_xlfn.XLOOKUP($B17,'Paste Here'!$A:$A,'Paste Here'!H:H),0) -> 0 | J17: =IFERROR(_xlfn.XLOOKUP($B17,'Paste Here'!$A:$A,'Paste Here'!I:I),0) -> 0 | K17: =IFERROR(_xlfn.XLOOKUP($B17,'Paste Here'!$A:$A,'Paste Here'!J:J),0) -> 0 | L17: =IFERROR(_xlfn.XLOOKUP($B17,'Paste Here'!$A:$A,'Paste Here'!K:K),0) -> 0 | M17: =IFERROR(_xlfn.XLOOKUP($B17,'Paste Here'!$A:$A,'Paste Here'!L:L),0) -> 0 | N17: =IFERROR(_xlfn.XLOOKUP($B17,'Paste Here'!$A:$A,'Paste Here'!M:M),0) -> 0 | O17: =IFERROR(_xlfn.XLOOKUP($B17,'Paste Here'!$A:$A,'Paste Here'!N:N),0) -> 0 | P17: =IFERROR(_xlfn.XLOOKUP($B17,'Paste Here'!$A:$A,'Paste Here'!O:O),0) -> 0 | Q17: =IFERROR(_xlfn.XLOOKUP($B17,'Paste Here'!$A:$A,'Paste Here'!P:P),0) -> 0 | R17: =IFERROR(_xlfn.XLOOKUP($B17,'Paste Here'!$A:$A,'Paste Here'!Q:Q),0) -> 0 | S17: =IFERROR(_xlfn.XLOOKUP($B17,'Paste Here'!$A:$A,'Paste Here'!R:R),0) -> 0 | T17: =IFERROR(_xlfn.XLOOKUP($B17,'Paste Here'!$A:$A,'Paste Here'!S:S),0) -> 0 | U17: =IFERROR(_xlfn.XLOOKUP($B17,'Paste Here'!$A:$A,'Paste Here'!T:T),0) -> 0 | V17: =IFERROR(_xlfn.XLOOKUP($B17,'Paste Here'!$A:$A,'Paste Here'!U:U),0) -> 0 | W17: =IFERROR(_xlfn.XLOOKUP($B17,'Paste Here'!$A:$A,'Paste Here'!V:V),0) -> 0 | X17: =IFERROR(_xlfn.XLOOKUP($B17,'Paste Here'!$A:$A,'Paste Here'!W:W),0) -> 0 | Y17: =IFERROR(_xlfn.XLOOKUP($B17,'Paste Here'!$A:$A,'Paste Here'!X:X),0) -> 0 | Z17: =IFERROR(_xlfn.XLOOKUP($B17,'Paste Here'!$A:$A,'Paste Here'!Y:Y),0) -> 0 | AA17: =IFERROR(_xlfn.XLOOKUP($B17,'Paste Here'!$A:$A,'Paste Here'!Z:Z),0) -> 0 | AB17: =IFERROR(_xlfn.XLOOKUP($B17,'Paste Here'!$A:$A,'Paste Here'!AA:AA),0) -> 0 | AC17: =IFERROR(_xlfn.XLOOKUP($B17,'Paste Here'!$A:$A,'Paste Here'!AB:AB),0) -> 0 | AD17: =IFERROR(_xlfn.XLOOKUP($B17,'Paste Here'!$A:$A,'Paste Here'!AC:AC),0) -> 0 | AE17: =IFERROR(_xlfn.XLOOKUP($B17,'Paste Here'!$A:$A,'Paste Here'!AD:AD),0) -> 0 | AF17: =IFERROR(_xlfn.XLOOKUP($B17,'Paste Here'!$A:$A,'Paste Here'!AE:AE),0) -> 0 | AG17: =IFERROR(_xlfn.XLOOKUP($B17,'Paste Here'!$A:$A,'Paste Here'!AF:AF),0) -> 0 | AH17: =IFERROR(_xlfn.XLOOKUP($B17,'Paste Here'!$A:$A,'Paste Here'!AG:AG),0) -> 0
A18: Transit OUT | B18: DC Out from Stock to STO | C18: =IFERROR(_xlfn.XLOOKUP($B18,'Paste Here'!$A:$A,'Paste Here'!B:B),0) -> 10007.477 | D18: =IFERROR(_xlfn.XLOOKUP($B18,'Paste Here'!$A:$A,'Paste Here'!C:C),0) -> 9971.09 | E18: =IFERROR(_xlfn.XLOOKUP($B18,'Paste Here'!$A:$A,'Paste Here'!D:D),0) -> 8690.573 | F18: =IFERROR(_xlfn.XLOOKUP($B18,'Paste Here'!$A:$A,'Paste Here'!E:E),0) -> 8999.521 | G18: =IFERROR(_xlfn.XLOOKUP($B18,'Paste Here'!$A:$A,'Paste Here'!F:F),0) -> 10979.087 | H18: =IFERROR(_xlfn.XLOOKUP($B18,'Paste Here'!$A:$A,'Paste Here'!G:G),0) -> 10368.393 | I18: =IFERROR(_xlfn.XLOOKUP($B18,'Paste Here'!$A:$A,'Paste Here'!H:H),0) -> 13011.914 | J18: =IFERROR(_xlfn.XLOOKUP($B18,'Paste Here'!$A:$A,'Paste Here'!I:I),0) -> 10361.632 | K18: =IFERROR(_xlfn.XLOOKUP($B18,'Paste Here'!$A:$A,'Paste Here'!J:J),0) -> 9605.3559 | L18: =IFERROR(_xlfn.XLOOKUP($B18,'Paste Here'!$A:$A,'Paste Here'!K:K),0) -> 9730.1158 | M18: =IFERROR(_xlfn.XLOOKUP($B18,'Paste Here'!$A:$A,'Paste Here'!L:L),0) -> 9577.47 | N18: =IFERROR(_xlfn.XLOOKUP($B18,'Paste Here'!$A:$A,'Paste Here'!M:M),0) -> 9686.05 | O18: =IFERROR(_xlfn.XLOOKUP($B18,'Paste Here'!$A:$A,'Paste Here'!N:N),0) -> 10576.204 | P18: =IFERROR(_xlfn.XLOOKUP($B18,'Paste Here'!$A:$A,'Paste Here'!O:O),0) -> 10232.15 | Q18: =IFERROR(_xlfn.XLOOKUP($B18,'Paste Here'!$A:$A,'Paste Here'!P:P),0) -> 9955.74 | R18: =IFERROR(_xlfn.XLOOKUP($B18,'Paste Here'!$A:$A,'Paste Here'!Q:Q),0) -> 9866.92 | S18: =IFERROR(_xlfn.XLOOKUP($B18,'Paste Here'!$A:$A,'Paste Here'!R:R),0) -> 9510.11 | T18: =IFERROR(_xlfn.XLOOKUP($B18,'Paste Here'!$A:$A,'Paste Here'!S:S),0) -> 11271.228 | U18: =IFERROR(_xlfn.XLOOKUP($B18,'Paste Here'!$A:$A,'Paste Here'!T:T),0) -> 9922.08 | V18: =IFERROR(_xlfn.XLOOKUP($B18,'Paste Here'!$A:$A,'Paste Here'!U:U),0) -> 8213.43 | W18: =IFERROR(_xlfn.XLOOKUP($B18,'Paste Here'!$A:$A,'Paste Here'!V:V),0) -> 7736.6697 | X18: =IFERROR(_xlfn.XLOOKUP($B18,'Paste Here'!$A:$A,'Paste Here'!W:W),0) -> 8425.5584 | Y18: =IFERROR(_xlfn.XLOOKUP($B18,'Paste Here'!$A:$A,'Paste Here'!X:X),0) -> 10522.06 | Z18: =IFERROR(_xlfn.XLOOKUP($B18,'Paste Here'!$A:$A,'Paste Here'!Y:Y),0) -> 10053.91 | AA18: =IFERROR(_xlfn.XLOOKUP($B18,'Paste Here'!$A:$A,'Paste Here'!Z:Z),0) -> 9648.93 | AB18: =IFERROR(_xlfn.XLOOKUP($B18,'Paste Here'!$A:$A,'Paste Here'!AA:AA),0) -> 8724.967 | AC18: =IFERROR(_xlfn.XLOOKUP($B18,'Paste Here'!$A:$A,'Paste Here'!AB:AB),0) -> 8859.7761 | AD18: =IFERROR(_xlfn.XLOOKUP($B18,'Paste Here'!$A:$A,'Paste Here'!AC:AC),0) -> 8737.9016 | AE18: =IFERROR(_xlfn.XLOOKUP($B18,'Paste Here'!$A:$A,'Paste Here'!AD:AD),0) -> 8736.85 | AF18: =IFERROR(_xlfn.XLOOKUP($B18,'Paste Here'!$A:$A,'Paste Here'!AE:AE),0) -> 8813.888 | AG18: =IFERROR(_xlfn.XLOOKUP($B18,'Paste Here'!$A:$A,'Paste Here'!AF:AF),0) -> 11255.76 | AH18: =IFERROR(_xlfn.XLOOKUP($B18,'Paste Here'!$A:$A,'Paste Here'!AG:AG),0) -> 8833.2
A19: DC Out from Stock to CDC | B19: DC Out from Stock to CDC | C19: =IFERROR(_xlfn.XLOOKUP($B19,'Paste Here'!$A:$A,'Paste Here'!B:B),0) -> 3629.419 | D19: =IFERROR(_xlfn.XLOOKUP($B19,'Paste Here'!$A:$A,'Paste Here'!C:C),0) -> 3876.867 | E19: =IFERROR(_xlfn.XLOOKUP($B19,'Paste Here'!$A:$A,'Paste Here'!D:D),0) -> 3382.087 | F19: =IFERROR(_xlfn.XLOOKUP($B19,'Paste Here'!$A:$A,'Paste Here'!E:E),0) -> 4102.25 | G19: =IFERROR(_xlfn.XLOOKUP($B19,'Paste Here'!$A:$A,'Paste Here'!F:F),0) -> 3643.755 | H19: =IFERROR(_xlfn.XLOOKUP($B19,'Paste Here'!$A:$A,'Paste Here'!G:G),0) -> 3723.711 | I19: =IFERROR(_xlfn.XLOOKUP($B19,'Paste Here'!$A:$A,'Paste Here'!H:H),0) -> 3894.4362 | J19: =IFERROR(_xlfn.XLOOKUP($B19,'Paste Here'!$A:$A,'Paste Here'!I:I),0) -> 3725.5276 | K19: =IFERROR(_xlfn.XLOOKUP($B19,'Paste Here'!$A:$A,'Paste Here'!J:J),0) -> 3596.4441 | L19: =IFERROR(_xlfn.XLOOKUP($B19,'Paste Here'!$A:$A,'Paste Here'!K:K),0) -> 3562.7742 | M19: =IFERROR(_xlfn.XLOOKUP($B19,'Paste Here'!$A:$A,'Paste Here'!L:L),0) -> 3578.61 | N19: =IFERROR(_xlfn.XLOOKUP($B19,'Paste Here'!$A:$A,'Paste Here'!M:M),0) -> 3393.69 | O19: =IFERROR(_xlfn.XLOOKUP($B19,'Paste Here'!$A:$A,'Paste Here'!N:N),0) -> 3632.1565 | P19: =IFERROR(_xlfn.XLOOKUP($B19,'Paste Here'!$A:$A,'Paste Here'!O:O),0) -> 3602.37 | Q19: =IFERROR(_xlfn.XLOOKUP($B19,'Paste Here'!$A:$A,'Paste Here'!P:P),0) -> 3656.93 | R19: =IFERROR(_xlfn.XLOOKUP($B19,'Paste Here'!$A:$A,'Paste Here'!Q:Q),0) -> 3469.19 | S19: =IFERROR(_xlfn.XLOOKUP($B19,'Paste Here'!$A:$A,'Paste Here'!R:R),0) -> 3889.34 | T19: =IFERROR(_xlfn.XLOOKUP($B19,'Paste Here'!$A:$A,'Paste Here'!S:S),0) -> 4242.3723 | U19: =IFERROR(_xlfn.XLOOKUP($B19,'Paste Here'!$A:$A,'Paste Here'!T:T),0) -> 3472.46 | V19: =IFERROR(_xlfn.XLOOKUP($B19,'Paste Here'!$A:$A,'Paste Here'!U:U),0) -> 2749.18 | W19: =IFERROR(_xlfn.XLOOKUP($B19,'Paste Here'!$A:$A,'Paste Here'!V:V),0) -> 2400.7503 | X19: =IFERROR(_xlfn.XLOOKUP($B19,'Paste Here'!$A:$A,'Paste Here'!W:W),0) -> 3347.3916 | Y19: =IFERROR(_xlfn.XLOOKUP($B19,'Paste Here'!$A:$A,'Paste Here'!X:X),0) -> 3794.37 | Z19: =IFERROR(_xlfn.XLOOKUP($B19,'Paste Here'!$A:$A,'Paste Here'!Y:Y),0) -> 4661.74 | AA19: =IFERROR(_xlfn.XLOOKUP($B19,'Paste Here'!$A:$A,'Paste Here'!Z:Z),0) -> 4443.26 | AB19: =IFERROR(_xlfn.XLOOKUP($B19,'Paste Here'!$A:$A,'Paste Here'!AA:AA),0) -> 3766.813 | AC19: =IFERROR(_xlfn.XLOOKUP($B19,'Paste Here'!$A:$A,'Paste Here'!AB:AB),0) -> 3779.3439 | AD19: =IFERROR(_xlfn.XLOOKUP($B19,'Paste Here'!$A:$A,'Paste Here'!AC:AC),0) -> 3724.1984 | AE19: =IFERROR(_xlfn.XLOOKUP($B19,'Paste Here'!$A:$A,'Paste Here'!AD:AD),0) -> 3888.13 | AF19: =IFERROR(_xlfn.XLOOKUP($B19,'Paste Here'!$A:$A,'Paste Here'!AE:AE),0) -> 4096.512 | AG19: =IFERROR(_xlfn.XLOOKUP($B19,'Paste Here'!$A:$A,'Paste Here'!AF:AF),0) -> 4389.33 | AH19: =IFERROR(_xlfn.XLOOKUP($B19,'Paste Here'!$A:$A,'Paste Here'!AG:AG),0) -> 3496.8
B20: DC Out from Stock to other BU | C20: =IFERROR(_xlfn.XLOOKUP($B20,'Paste Here'!$A:$A,'Paste Here'!B:B),0) -> 297.823 | D20: =IFERROR(_xlfn.XLOOKUP($B20,'Paste Here'!$A:$A,'Paste Here'!C:C),0) -> 0 | E20: =IFERROR(_xlfn.XLOOKUP($B20,'Paste Here'!$A:$A,'Paste Here'!D:D),0) -> 0 | F20: =IFERROR(_xlfn.XLOOKUP($B20,'Paste Here'!$A:$A,'Paste Here'!E:E),0) -> 0 | G20: =IFERROR(_xlfn.XLOOKUP($B20,'Paste Here'!$A:$A,'Paste Here'!F:F),0) -> 201.254 | H20: =IFERROR(_xlfn.XLOOKUP($B20,'Paste Here'!$A:$A,'Paste Here'!G:G),0) -> 40.455 | I20: =IFERROR(_xlfn.XLOOKUP($B20,'Paste Here'!$A:$A,'Paste Here'!H:H),0) -> 0 | J20: =IFERROR(_xlfn.XLOOKUP($B20,'Paste Here'!$A:$A,'Paste Here'!I:I),0) -> 0 | K20: =IFERROR(_xlfn.XLOOKUP($B20,'Paste Here'!$A:$A,'Paste Here'!J:J),0) -> 0 | L20: =IFERROR(_xlfn.XLOOKUP($B20,'Paste Here'!$A:$A,'Paste Here'!K:K),0) -> 0 | M20: =IFERROR(_xlfn.XLOOKUP($B20,'Paste Here'!$A:$A,'Paste Here'!L:L),0) -> 0 | N20: =IFERROR(_xlfn.XLOOKUP($B20,'Paste Here'!$A:$A,'Paste Here'!M:M),0) -> 0 | O20: =IFERROR(_xlfn.XLOOKUP($B20,'Paste Here'!$A:$A,'Paste Here'!N:N),0) -> 0 | P20: =IFERROR(_xlfn.XLOOKUP($B20,'Paste Here'!$A:$A,'Paste Here'!O:O),0) -> 0 | Q20: =IFERROR(_xlfn.XLOOKUP($B20,'Paste Here'!$A:$A,'Paste Here'!P:P),0) -> 0 | R20: =IFERROR(_xlfn.XLOOKUP($B20,'Paste Here'!$A:$A,'Paste Here'!Q:Q),0) -> 0 | S20: =IFERROR(_xlfn.XLOOKUP($B20,'Paste Here'!$A:$A,'Paste Here'!R:R),0) -> 0 | T20: =IFERROR(_xlfn.XLOOKUP($B20,'Paste Here'!$A:$A,'Paste Here'!S:S),0) -> 0 | U20: =IFERROR(_xlfn.XLOOKUP($B20,'Paste Here'!$A:$A,'Paste Here'!T:T),0) -> 0 | V20: =IFERROR(_xlfn.XLOOKUP($B20,'Paste Here'!$A:$A,'Paste Here'!U:U),0) -> 0 | W20: =IFERROR(_xlfn.XLOOKUP($B20,'Paste Here'!$A:$A,'Paste Here'!V:V),0) -> 0 | X20: =IFERROR(_xlfn.XLOOKUP($B20,'Paste Here'!$A:$A,'Paste Here'!W:W),0) -> 0 | Y20: =IFERROR(_xlfn.XLOOKUP($B20,'Paste Here'!$A:$A,'Paste Here'!X:X),0) -> 0 | Z20: =IFERROR(_xlfn.XLOOKUP($B20,'Paste Here'!$A:$A,'Paste Here'!Y:Y),0) -> 0 | AA20: =IFERROR(_xlfn.XLOOKUP($B20,'Paste Here'!$A:$A,'Paste Here'!Z:Z),0) -> 0 | AB20: =IFERROR(_xlfn.XLOOKUP($B20,'Paste Here'!$A:$A,'Paste Here'!AA:AA),0) -> 0 | AC20: =IFERROR(_xlfn.XLOOKUP($B20,'Paste Here'!$A:$A,'Paste Here'!AB:AB),0) -> 0 | AD20: =IFERROR(_xlfn.XLOOKUP($B20,'Paste Here'!$A:$A,'Paste Here'!AC:AC),0) -> 0 | AE20: =IFERROR(_xlfn.XLOOKUP($B20,'Paste Here'!$A:$A,'Paste Here'!AD:AD),0) -> 0 | AF20: =IFERROR(_xlfn.XLOOKUP($B20,'Paste Here'!$A:$A,'Paste Here'!AE:AE),0) -> 0 | AG20: =IFERROR(_xlfn.XLOOKUP($B20,'Paste Here'!$A:$A,'Paste Here'!AF:AF),0) -> 0 | AH20: =IFERROR(_xlfn.XLOOKUP($B20,'Paste Here'!$A:$A,'Paste Here'!AG:AG),0) -> 0
A21: Picking m3 | B21: Total DC Out from Stock | C21: =IFERROR(_xlfn.XLOOKUP($B21,'Paste Here'!$A:$A,'Paste Here'!B:B),0) -> 13934.719 | D21: =IFERROR(_xlfn.XLOOKUP($B21,'Paste Here'!$A:$A,'Paste Here'!C:C),0) -> 13847.957 | E21: =IFERROR(_xlfn.XLOOKUP($B21,'Paste Here'!$A:$A,'Paste Here'!D:D),0) -> 12072.66 | F21: =IFERROR(_xlfn.XLOOKUP($B21,'Paste Here'!$A:$A,'Paste Here'!E:E),0) -> 13101.771 | G21: =IFERROR(_xlfn.XLOOKUP($B21,'Paste Here'!$A:$A,'Paste Here'!F:F),0) -> 14824.096 | H21: =IFERROR(_xlfn.XLOOKUP($B21,'Paste Here'!$A:$A,'Paste Here'!G:G),0) -> 14132.559 | I21: =IFERROR(_xlfn.XLOOKUP($B21,'Paste Here'!$A:$A,'Paste Here'!H:H),0) -> 16906.35 | J21: =IFERROR(_xlfn.XLOOKUP($B21,'Paste Here'!$A:$A,'Paste Here'!I:I),0) -> 14087.16 | K21: =IFERROR(_xlfn.XLOOKUP($B21,'Paste Here'!$A:$A,'Paste Here'!J:J),0) -> 13201.8 | L21: =IFERROR(_xlfn.XLOOKUP($B21,'Paste Here'!$A:$A,'Paste Here'!K:K),0) -> 13292.89 | M21: =IFERROR(_xlfn.XLOOKUP($B21,'Paste Here'!$A:$A,'Paste Here'!L:L),0) -> 13156.08 | N21: =IFERROR(_xlfn.XLOOKUP($B21,'Paste Here'!$A:$A,'Paste Here'!M:M),0) -> 13079.74 | O21: =IFERROR(_xlfn.XLOOKUP($B21,'Paste Here'!$A:$A,'Paste Here'!N:N),0) -> 14208.36 | P21: =IFERROR(_xlfn.XLOOKUP($B21,'Paste Here'!$A:$A,'Paste Here'!O:O),0) -> 13834.52 | Q21: =IFERROR(_xlfn.XLOOKUP($B21,'Paste Here'!$A:$A,'Paste Here'!P:P),0) -> 13612.67 | R21: =IFERROR(_xlfn.XLOOKUP($B21,'Paste Here'!$A:$A,'Paste Here'!Q:Q),0) -> 13336.11 | S21: =IFERROR(_xlfn.XLOOKUP($B21,'Paste Here'!$A:$A,'Paste Here'!R:R),0) -> 13399.45 | T21: =IFERROR(_xlfn.XLOOKUP($B21,'Paste Here'!$A:$A,'Paste Here'!S:S),0) -> 15513.6 | U21: =IFERROR(_xlfn.XLOOKUP($B21,'Paste Here'!$A:$A,'Paste Here'!T:T),0) -> 13394.54 | V21: =IFERROR(_xlfn.XLOOKUP($B21,'Paste Here'!$A:$A,'Paste Here'!U:U),0) -> 10962.61 | W21: =IFERROR(_xlfn.XLOOKUP($B21,'Paste Here'!$A:$A,'Paste Here'!V:V),0) -> 10137.42 | X21: =IFERROR(_xlfn.XLOOKUP($B21,'Paste Here'!$A:$A,'Paste Here'!W:W),0) -> 11772.95 | Y21: =IFERROR(_xlfn.XLOOKUP($B21,'Paste Here'!$A:$A,'Paste Here'!X:X),0) -> 14316.43 | Z21: =IFERROR(_xlfn.XLOOKUP($B21,'Paste Here'!$A:$A,'Paste Here'!Y:Y),0) -> 14715.65 | AA21: =IFERROR(_xlfn.XLOOKUP($B21,'Paste Here'!$A:$A,'Paste Here'!Z:Z),0) -> 14092.19 | AB21: =IFERROR(_xlfn.XLOOKUP($B21,'Paste Here'!$A:$A,'Paste Here'!AA:AA),0) -> 12491.78 | AC21: =IFERROR(_xlfn.XLOOKUP($B21,'Paste Here'!$A:$A,'Paste Here'!AB:AB),0) -> 12639.12 | AD21: =IFERROR(_xlfn.XLOOKUP($B21,'Paste Here'!$A:$A,'Paste Here'!AC:AC),0) -> 12462.1 | AE21: =IFERROR(_xlfn.XLOOKUP($B21,'Paste Here'!$A:$A,'Paste Here'!AD:AD),0) -> 12624.98 | AF21: =IFERROR(_xlfn.XLOOKUP($B21,'Paste Here'!$A:$A,'Paste Here'!AE:AE),0) -> 12910.4 | AG21: =IFERROR(_xlfn.XLOOKUP($B21,'Paste Here'!$A:$A,'Paste Here'!AF:AF),0) -> 15645.09 | AH21: =IFERROR(_xlfn.XLOOKUP($B21,'Paste Here'!$A:$A,'Paste Here'!AG:AG),0) -> 12330
B22: Total DC Out Transit | C22: =IFERROR(_xlfn.XLOOKUP($B22,'Paste Here'!$A:$A,'Paste Here'!B:B),0) -> 6815.12 | D22: =IFERROR(_xlfn.XLOOKUP($B22,'Paste Here'!$A:$A,'Paste Here'!C:C),0) -> 7643.706 | E22: =IFERROR(_xlfn.XLOOKUP($B22,'Paste Here'!$A:$A,'Paste Here'!D:D),0) -> 8230.709 | F22: =IFERROR(_xlfn.XLOOKUP($B22,'Paste Here'!$A:$A,'Paste Here'!E:E),0) -> 7483.62 | G22: =IFERROR(_xlfn.XLOOKUP($B22,'Paste Here'!$A:$A,'Paste Here'!F:F),0) -> 7821.638 | H22: =IFERROR(_xlfn.XLOOKUP($B22,'Paste Here'!$A:$A,'Paste Here'!G:G),0) -> 7754.769 | I22: =IFERROR(_xlfn.XLOOKUP($B22,'Paste Here'!$A:$A,'Paste Here'!H:H),0) -> 11180.797 | J22: =IFERROR(_xlfn.XLOOKUP($B22,'Paste Here'!$A:$A,'Paste Here'!I:I),0) -> 8371.813 | K22: =IFERROR(_xlfn.XLOOKUP($B22,'Paste Here'!$A:$A,'Paste Here'!J:J),0) -> 10117.606 | L22: =IFERROR(_xlfn.XLOOKUP($B22,'Paste Here'!$A:$A,'Paste Here'!K:K),0) -> 8669.836 | M22: =IFERROR(_xlfn.XLOOKUP($B22,'Paste Here'!$A:$A,'Paste Here'!L:L),0) -> 8260.056 | N22: =IFERROR(_xlfn.XLOOKUP($B22,'Paste Here'!$A:$A,'Paste Here'!M:M),0) -> 9513.43 | O22: =IFERROR(_xlfn.XLOOKUP($B22,'Paste Here'!$A:$A,'Paste Here'!N:N),0) -> 10133.84 | P22: =IFERROR(_xlfn.XLOOKUP($B22,'Paste Here'!$A:$A,'Paste Here'!O:O),0) -> 9543.5 | Q22: =IFERROR(_xlfn.XLOOKUP($B22,'Paste Here'!$A:$A,'Paste Here'!P:P),0) -> 9795 | R22: =IFERROR(_xlfn.XLOOKUP($B22,'Paste Here'!$A:$A,'Paste Here'!Q:Q),0) -> 9766.62 | S22: =IFERROR(_xlfn.XLOOKUP($B22,'Paste Here'!$A:$A,'Paste Here'!R:R),0) -> 9361.33 | T22: =IFERROR(_xlfn.XLOOKUP($B22,'Paste Here'!$A:$A,'Paste Here'!S:S),0) -> 9499.2 | U22: =IFERROR(_xlfn.XLOOKUP($B22,'Paste Here'!$A:$A,'Paste Here'!T:T),0) -> 9012.3 | V22: =IFERROR(_xlfn.XLOOKUP($B22,'Paste Here'!$A:$A,'Paste Here'!U:U),0) -> 7789.93 | W22: =IFERROR(_xlfn.XLOOKUP($B22,'Paste Here'!$A:$A,'Paste Here'!V:V),0) -> 7887.95 | X22: =IFERROR(_xlfn.XLOOKUP($B22,'Paste Here'!$A:$A,'Paste Here'!W:W),0) -> 9269.71 | Y22: =IFERROR(_xlfn.XLOOKUP($B22,'Paste Here'!$A:$A,'Paste Here'!X:X),0) -> 9218.44 | Z22: =IFERROR(_xlfn.XLOOKUP($B22,'Paste Here'!$A:$A,'Paste Here'!Y:Y),0) -> 9113.91 | AA22: =IFERROR(_xlfn.XLOOKUP($B22,'Paste Here'!$A:$A,'Paste Here'!Z:Z),0) -> 5638.46 | AB22: =IFERROR(_xlfn.XLOOKUP($B22,'Paste Here'!$A:$A,'Paste Here'!AA:AA),0) -> 6800.35 | AC22: =IFERROR(_xlfn.XLOOKUP($B22,'Paste Here'!$A:$A,'Paste Here'!AB:AB),0) -> 8111.14 | AD22: =IFERROR(_xlfn.XLOOKUP($B22,'Paste Here'!$A:$A,'Paste Here'!AC:AC),0) -> 8464.46 | AE22: =IFERROR(_xlfn.XLOOKUP($B22,'Paste Here'!$A:$A,'Paste Here'!AD:AD),0) -> 8640.17 | AF22: =IFERROR(_xlfn.XLOOKUP($B22,'Paste Here'!$A:$A,'Paste Here'!AE:AE),0) -> 8750.52 | AG22: =IFERROR(_xlfn.XLOOKUP($B22,'Paste Here'!$A:$A,'Paste Here'!AF:AF),0) -> 9396.13 | AH22: =IFERROR(_xlfn.XLOOKUP($B22,'Paste Here'!$A:$A,'Paste Here'!AG:AG),0) -> 8209.99
A23: Picking OL | B23: Total Outbound | C23: =IFERROR(_xlfn.XLOOKUP($B23,'Paste Here'!$A:$A,'Paste Here'!B:B),0) -> 20749.839 | D23: =IFERROR(_xlfn.XLOOKUP($B23,'Paste Here'!$A:$A,'Paste Here'!C:C),0) -> 21491.663 | E23: =IFERROR(_xlfn.XLOOKUP($B23,'Paste Here'!$A:$A,'Paste Here'!D:D),0) -> 20303.369 | F23: =IFERROR(_xlfn.XLOOKUP($B23,'Paste Here'!$A:$A,'Paste Here'!E:E),0) -> 20585.391 | G23: =IFERROR(_xlfn.XLOOKUP($B23,'Paste Here'!$A:$A,'Paste Here'!F:F),0) -> 22645.734 | H23: =IFERROR(_xlfn.XLOOKUP($B23,'Paste Here'!$A:$A,'Paste Here'!G:G),0) -> 21887.328 | I23: =IFERROR(_xlfn.XLOOKUP($B23,'Paste Here'!$A:$A,'Paste Here'!H:H),0) -> 28087.147 | J23: =IFERROR(_xlfn.XLOOKUP($B23,'Paste Here'!$A:$A,'Paste Here'!I:I),0) -> 22458.973 | K23: =IFERROR(_xlfn.XLOOKUP($B23,'Paste Here'!$A:$A,'Paste Here'!J:J),0) -> 23319.406 | L23: =IFERROR(_xlfn.XLOOKUP($B23,'Paste Here'!$A:$A,'Paste Here'!K:K),0) -> 21962.726 | M23: =IFERROR(_xlfn.XLOOKUP($B23,'Paste Here'!$A:$A,'Paste Here'!L:L),0) -> 21416.136 | N23: =IFERROR(_xlfn.XLOOKUP($B23,'Paste Here'!$A:$A,'Paste Here'!M:M),0) -> 22593.17 | O23: =IFERROR(_xlfn.XLOOKUP($B23,'Paste Here'!$A:$A,'Paste Here'!N:N),0) -> 24342.2 | P23: =IFERROR(_xlfn.XLOOKUP($B23,'Paste Here'!$A:$A,'Paste Here'!O:O),0) -> 23378.02 | Q23: =IFERROR(_xlfn.XLOOKUP($B23,'Paste Here'!$A:$A,'Paste Here'!P:P),0) -> 23407.67 | R23: =IFERROR(_xlfn.XLOOKUP($B23,'Paste Here'!$A:$A,'Paste Here'!Q:Q),0) -> 23102.73 | S23: =IFERROR(_xlfn.XLOOKUP($B23,'Paste Here'!$A:$A,'Paste Here'!R:R),0) -> 22760.78 | T23: =IFERROR(_xlfn.XLOOKUP($B23,'Paste Here'!$A:$A,'Paste Here'!S:S),0) -> 25012.8 | U23: =IFERROR(_xlfn.XLOOKUP($B23,'Paste Here'!$A:$A,'Paste Here'!T:T),0) -> 22406.84 | V23: =IFERROR(_xlfn.XLOOKUP($B23,'Paste Here'!$A:$A,'Paste Here'!U:U),0) -> 18752.54 | W23: =IFERROR(_xlfn.XLOOKUP($B23,'Paste Here'!$A:$A,'Paste Here'!V:V),0) -> 18025.37 | X23: =IFERROR(_xlfn.XLOOKUP($B23,'Paste Here'!$A:$A,'Paste Here'!W:W),0) -> 21042.66 | Y23: =IFERROR(_xlfn.XLOOKUP($B23,'Paste Here'!$A:$A,'Paste Here'!X:X),0) -> 23534.87 | Z23: =IFERROR(_xlfn.XLOOKUP($B23,'Paste Here'!$A:$A,'Paste Here'!Y:Y),0) -> 23829.56 | AA23: =IFERROR(_xlfn.XLOOKUP($B23,'Paste Here'!$A:$A,'Paste Here'!Z:Z),0) -> 19730.65 | AB23: =IFERROR(_xlfn.XLOOKUP($B23,'Paste Here'!$A:$A,'Paste Here'!AA:AA),0) -> 19292.13 | AC23: =IFERROR(_xlfn.XLOOKUP($B23,'Paste Here'!$A:$A,'Paste Here'!AB:AB),0) -> 20750.26 | AD23: =IFERROR(_xlfn.XLOOKUP($B23,'Paste Here'!$A:$A,'Paste Here'!AC:AC),0) -> 20926.56 | AE23: =IFERROR(_xlfn.XLOOKUP($B23,'Paste Here'!$A:$A,'Paste Here'!AD:AD),0) -> 21265.15 | AF23: =IFERROR(_xlfn.XLOOKUP($B23,'Paste Here'!$A:$A,'Paste Here'!AE:AE),0) -> 21660.92 | AG23: =IFERROR(_xlfn.XLOOKUP($B23,'Paste Here'!$A:$A,'Paste Here'!AF:AF),0) -> 25041.22 | AH23: =IFERROR(_xlfn.XLOOKUP($B23,'Paste Here'!$A:$A,'Paste Here'!AG:AG),0) -> 20539.99
B24: Picking % | C24: =IFERROR(_xlfn.XLOOKUP($B24,'Paste Here'!$A:$A,'Paste Here'!B:B),0) -> 0.057765427 | D24: =IFERROR(_xlfn.XLOOKUP($B24,'Paste Here'!$A:$A,'Paste Here'!C:C),0) -> 0.05707109 | E24: =IFERROR(_xlfn.XLOOKUP($B24,'Paste Here'!$A:$A,'Paste Here'!D:D),0) -> 0.082201934 | F24: =IFERROR(_xlfn.XLOOKUP($B24,'Paste Here'!$A:$A,'Paste Here'!E:E),0) -> 0.064379541 | G24: =IFERROR(_xlfn.XLOOKUP($B24,'Paste Here'!$A:$A,'Paste Here'!F:F),0) -> 0.073257486 | H24: =IFERROR(_xlfn.XLOOKUP($B24,'Paste Here'!$A:$A,'Paste Here'!G:G),0) -> 0.055953844 | I24: =IFERROR(_xlfn.XLOOKUP($B24,'Paste Here'!$A:$A,'Paste Here'!H:H),0) -> 0.065 | J24: =IFERROR(_xlfn.XLOOKUP($B24,'Paste Here'!$A:$A,'Paste Here'!I:I),0) -> 0.065 | K24: =IFERROR(_xlfn.XLOOKUP($B24,'Paste Here'!$A:$A,'Paste Here'!J:J),0) -> 0.065 | L24: =IFERROR(_xlfn.XLOOKUP($B24,'Paste Here'!$A:$A,'Paste Here'!K:K),0) -> 0.065 | M24: =IFERROR(_xlfn.XLOOKUP($B24,'Paste Here'!$A:$A,'Paste Here'!L:L),0) -> 0.065 | N24: =IFERROR(_xlfn.XLOOKUP($B24,'Paste Here'!$A:$A,'Paste Here'!M:M),0) -> 0.065 | O24: =IFERROR(_xlfn.XLOOKUP($B24,'Paste Here'!$A:$A,'Paste Here'!N:N),0) -> 0.065 | P24: =IFERROR(_xlfn.XLOOKUP($B24,'Paste Here'!$A:$A,'Paste Here'!O:O),0) -> 0.065 | Q24: =IFERROR(_xlfn.XLOOKUP($B24,'Paste Here'!$A:$A,'Paste Here'!P:P),0) -> 0.065 | R24: =IFERROR(_xlfn.XLOOKUP($B24,'Paste Here'!$A:$A,'Paste Here'!Q:Q),0) -> 0.065 | S24: =IFERROR(_xlfn.XLOOKUP($B24,'Paste Here'!$A:$A,'Paste Here'!R:R),0) -> 0.065 | T24: =IFERROR(_xlfn.XLOOKUP($B24,'Paste Here'!$A:$A,'Paste Here'!S:S),0) -> 0.065 | U24: =IFERROR(_xlfn.XLOOKUP($B24,'Paste Here'!$A:$A,'Paste Here'!T:T),0) -> 0.065 | V24: =IFERROR(_xlfn.XLOOKUP($B24,'Paste Here'!$A:$A,'Paste Here'!U:U),0) -> 0.065 | W24: =IFERROR(_xlfn.XLOOKUP($B24,'Paste Here'!$A:$A,'Paste Here'!V:V),0) -> 0.065 | X24: =IFERROR(_xlfn.XLOOKUP($B24,'Paste Here'!$A:$A,'Paste Here'!W:W),0) -> 0.065 | Y24: =IFERROR(_xlfn.XLOOKUP($B24,'Paste Here'!$A:$A,'Paste Here'!X:X),0) -> 0.065 | Z24: =IFERROR(_xlfn.XLOOKUP($B24,'Paste Here'!$A:$A,'Paste Here'!Y:Y),0) -> 0.065 | AA24: =IFERROR(_xlfn.XLOOKUP($B24,'Paste Here'!$A:$A,'Paste Here'!Z:Z),0) -> 0.065 | AB24: =IFERROR(_xlfn.XLOOKUP($B24,'Paste Here'!$A:$A,'Paste Here'!AA:AA),0) -> 0.065 | AC24: =IFERROR(_xlfn.XLOOKUP($B24,'Paste Here'!$A:$A,'Paste Here'!AB:AB),0) -> 0.065 | AD24: =IFERROR(_xlfn.XLOOKUP($B24,'Paste Here'!$A:$A,'Paste Here'!AC:AC),0) -> 0.065 | AE24: =IFERROR(_xlfn.XLOOKUP($B24,'Paste Here'!$A:$A,'Paste Here'!AD:AD),0) -> 0.065 | AF24: =IFERROR(_xlfn.XLOOKUP($B24,'Paste Here'!$A:$A,'Paste Here'!AE:AE),0) -> 0.065 | AG24: =IFERROR(_xlfn.XLOOKUP($B24,'Paste Here'!$A:$A,'Paste Here'!AF:AF),0) -> 0.065 | AH24: =IFERROR(_xlfn.XLOOKUP($B24,'Paste Here'!$A:$A,'Paste Here'!AG:AG),0) -> 0.065
